Workbook

Sheet Total
A1: Course Name ( New Students ) | B1: Quantity | E1: Menna | H1: Adham | K1: Akreman | Q1: Nourhan | W1: Mariam | Z1: Khalid
B2: West | C2: East | D2: Total | E2: West | F2: East | G2: Total | H2: West | I2: East | J2: Total | K2: West | L2: East | M2: Total | N2: West | O2: East | P2: Total | Q2: West | R2: East | S2: Total | T2: West | U2: East | V2: Total | W2: West | X2: East | Y2: Total | Z2: West | AA2: East | AB2: Total
A3: NLP | B3: 13 | C3: 0 | D3: =sum(B3:C3) -> 13 | E3: =(COUNTIF('NLP 1'!D4:D16,"*menna*")) -> 9 | F3: =COUNTIF(#REF!,"*menna*") -> 0 | G3: =sum(E3:F3) -> 9 | H3: =COUNTIF('NLP 1'!D4:D16,"*Adham*") -> 1 | I3: =COUNTIF(#REF!,"*Adham*") -> 0 | J3: =sum(H3:I3) -> 1 | K3: =COUNTIF('NLP 1'!D4:D16,"*Akreman*") -> 0 | L3: =COUNTIF(#REF!,"*Akreman*") -> 0 | M3: =sum(K3:L3) -> 0 | N3: =COUNTIF('NLP 1'!D4:D16,"*rasha*") -> 0 | O3: =COUNTIF(#REF!,"*rasha*") -> 0 | P3: =sum(N3:O3) -> 0 | Q3: =COUNTIF('NLP 1'!D4:D16,"*nourhan*") -> 2 | R3: =COUNTIF(#REF!,"*nourhan*") -> 0 | S3: =sum(Q3:R3) -> 2 | T3: =COUNTIF('NLP 1'!D4:D16,"*ashrakat*") -> 0 | U3: =COUNTIF(#REF!,"*ashrakat*") -> 0 | V3: =sum(T3:U3) -> 0 | W3: =COUNTIF('NLP 1'!D4:D16,"*mariam*") -> 0 | X3: =COUNTIF(#REF!,"*mariam*") -> 0 | Y3: =sum(W3:X3) -> 0 | Z3: =COUNTIF('NLP 1'!D4:D16,"*Khalid*") -> 0 | AA3: =COUNTIF(#REF!,"*khalid*") -> 0 | AB3: =sum(Z3:AA3) -> 0
A4: Enneagram | B4: =('Enn 1'!B41) -> 8 | C4: =('Enn 1'!O41) -> 5 | D4: =sum(B4:C4) -> 13 | E4: =COUNTIF('Enn 1'!D4:D40,"*menna*") -> 6 | F4: =COUNTIF('Enn 1'!Q4:Q40,"*menna*") -> 1 | G4: =sum(E4:F4) -> 7 | H4: =COUNTIF('Enn 1'!D4:D40,"*Adham*") -> 0 | I4: =COUNTIF('Enn 1'!Q4:Q40,"*Adham*") -> 0 | J4: =sum(H4:I4) -> 0 | K4: =COUNTIF('Enn 1'!D4:D40,"*Akreman*") -> 0 | L4: =COUNTIF('Enn 1'!Q4:Q40,"*Akreman*") -> 0 | M4: =sum(K4:L4) -> 0 | N4: =COUNTIF('Enn 1'!D4:D40,"*rasha*") -> 0 | O4: =COUNTIF('Enn 1'!Q4:Q40,"*rasha*") -> 0 | P4: =sum(N4:O4) -> 0 | Q4: =COUNTIF('Enn 1'!D4:D40,"*nourhan*") -> 1 | R4: =COUNTIF('Enn 1'!Q4:Q40,"*nourhan*") -> 2 | S4: =sum(Q4:R4) -> 3 | T4: =COUNTIF('Enn 1'!D4:D40,"*ashrakat*") -> 0 | U4: =COUNTIF('Enn 1'!Q4:Q40,"*ashrakat*") -> 0 | V4: =sum(T4:U4) -> 0 | W4: =COUNTIF('Enn 1'!D4:D40,"*mariam*") -> 0 | X4: =COUNTIF('Enn 1'!Q4:Q40,"*mariam*") -> 0 | Y4: =sum(W4:X4) -> 0 | Z4: =COUNTIF('Enn 1'!D4:D40,"*khalid*") -> 0 | AA4: =COUNTIF('Enn 1'!Q4:Q40,"*khalid*") -> 0 | AB4: =sum(Z4:AA4) -> 0
A5: Reiki | B5: =('Reiki D'!B41) -> 5 | C5: ='Reiki D'!O41 | D5: =sum(B5:C5) -> 5 | E5: =COUNTIF('Reiki D'!D4:D40,"*menna*") -> 2 | F5: =COUNTIF('Reiki D'!Q4:Q40,"*menna*") -> 5 | G5: =sum(E5:F5) -> 7 | H5: =COUNTIF('Reiki D'!D4:D40,"*Adham*") -> 0 | I5: =COUNTIF('Reiki D'!Q4:Q40,"*Adham*") -> 0 | J5: =sum(H5:I5) -> 0 | K5: =COUNTIF('Reiki D'!D4:D40,"*Akreman*") -> 0 | L5: =COUNTIF('Reiki D'!Q4:Q40,"*Akreman*") -> 0 | M5: =sum(K5:L5) -> 0 | N5: =COUNTIF('Reiki D'!D4:D40,"*rasha*") -> 0 | O5: =COUNTIF('Reiki D'!Q4:Q40,"*rasha*") -> 0 | P5: =sum(N5:O5) -> 0 | Q5: =COUNTIF('Reiki D'!D4:D40,"*nourhan*") -> 1 | R5: =COUNTIF('Reiki D'!Q4:Q40,"*nourhan*") -> 2 | S5: =sum(Q5:R5) -> 3 | T5: =COUNTIF('Reiki D'!D4:D40,"*ashrakat*") -> 0 | U5: =COUNTIF('Reiki D'!Q4:Q40,"*ashrakat*") -> 0 | V5: =sum(T5:U5) -> 0 | W5: =COUNTIF('Reiki D'!D4:D40,"*Mariam*") -> 2 | X5: =COUNTIF('Reiki D'!Q4:Q40,"*mariam*") -> 0 | Y5: =sum(W5:X5) -> 2 | Z5: =COUNTIF('Reiki D'!D4:D40,"*khalid*") -> 0 | AA5: =COUNTIF('Reiki D'!Q4:Q40,"*khalid*") -> 0 | AB5: =sum(Z5:AA5) -> 0
A6: Total | B6: =SUM(B3:B5) -> 26 | C6: =SUM(C3:C5) -> 5 | D6: =SUM(D3:D5) -> 31 | G6: =SUM(G3:G5) -> 23 | J6: =SUM(J3:J5) -> 1 | M6: =SUM(M3:M5) -> 0 | P6: =SUM(P3:P5) -> 0 | S6: =SUM(S3:S5) -> 8 | V6: =SUM(V3:V5) -> 0 | Y6: =SUM(Y3:Y5) -> 2 | AB6: =SUM(AB3:AB5) -> 0
D7: Total Conversion From Paid | G7: =G6/D6 -> 0.74193548 | J7: =J6/D6 -> 0.032258065 | M7: =M6/D6 -> 0 | P7: =P6/D6 -> 0 | S7: =S6/D6 -> 0.25806452 | V7: =V6/D6 -> 0 | Y7: =Y6/D6 -> 0.064516129 | AB7: =AB6/D6 -> 0
A10: Course Name | B10: Quantity
B11: West | C11: East | D11: Total
A12: Family Constellation | B12: ='FC D1'!B42 -> 9 | D12: =sum(B12:C12) -> 9
A13: CAW | B13: ='Mini CAW'!B43 -> 10 | C13: ='Mini CAW'!L43 -> 0 | D13: =sum(B13:C13) -> 10
A14: Total | B14: =sum(B10:B12) -> 9 | C14: =sum(C10:C12) -> 0 | D14: =sum(B14:C14) -> 9

Sheet Data
A1: Seller Name | B1: Caw | C1: Price
A2: Menna | B2: Participant | C2: 600
A3: Akreman | B3: Issue Holder | C3: 1800
A4: Rasha | B4: Employee P | C4: 300
A5: Nourhan | B5: Employee IH | C5: 900
A6: Mariam
A7: Adham

Sheet Enn 1
A1: Enneagram 1 (NC) 19-20 & 26-27 June | I1: Confirmation | J1: Attendance | N1: Enneagram 1 (AZ) 15-18 June | V1: Confirmation | W1: Attendance
A2: S. | B2: Client Name | C2: Phone Number | D2: Seller Name | E2: Payment | J2: Day 1 | K2: Day 2 | L2: Day 3 | M2: Day 4 | N2: S. | O2: Client Name | P2: Phone Number | Q2: Seller Name | R2: Payment | W2: Day 1 | X2: Day 2 | Y2: Day 3 | Z2: Day 4
E3: Course Fees | F3: Paid Amount | G3: Remaining Amount | H3: Notes | R3: Course Fees | S3: Paid Amount | T3: Remaining Amount | U3: Notes
A4: 1 | B4: Aya Ali | D4: Menna | E4: 4000 | F4: 4650 | G4: =E4-F4 -> -650 | H4: postponed | N4: 1 | O4: manal youssef | Q4: Menna | T4: =R4-S4 -> 0 | U4: last 2 days,postponed from may | Y4: done | Z4: done
A5: 2 | B5: Mihav Ibrahiem | C5: 0114 397 1526 | D5: Menna | E5: 4000 | F5: 4000 | G5: =E5-F5 -> 0 | J5: done | N5: 2 | O5: sohila shaltot | P5: 1273700189 | Q5: Nourhan | R5: 4000 | S5: 4000 | T5: =R5-S5 -> 0 | W5: done | Y5: done | Z5: done
A6: 3 | B6: Nada Dardery | C6: 0102 671 6798 | D6: Menna | E6: 4000 | F6: 2000 | G6: =E6-F6 -> 2000 | J6: done | N6: 3 | O6: amr salem | P6: 1272177213 | Q6: Nourhan | R6: 4000 | S6: 4000 | T6: =R6-S6 -> 0 | W6: done | Z6: done
A7: 4 | B7: Peter Nayem | C7: 0106 505 0496 | D7: Menna | E7: 4000 | F7: 4000 | G7: =E7-F7 -> 0 | J7: done | N7: 4 | O7: mai khalefa | R7: 4000 | T7: =R7-S7 -> 4000 | W7: done | Z7: done
A8: 5 | B8: khalid l menyawi | C8: 1023388401 | D8: Nourhan | E8: 4000 | F8: 4000 | G8: =E8-F8 -> 0 | J8: done | N8: 5 | O8: Akreman | R8: 4000 | T8: =R8-S8 -> 4000 | U8: Staff | W8: done | Y8: done | Z8: done
A9: 6 | B9: Ghada Abdel Khaliek | C9: 0122 216 1600 | D9: Menna | E9: 4000 | F9: 4000 | J9: done | R9: 0 | T9: =R9-S9 -> 0
A10: 7 | B10: Doaa Hamed | C10: 0109 771 8946 | D10: Menna | E10: 4000 | F10: 4000 | G10: =E10-F10 -> 0 | J10: done | R10: 0 | T10: =R10-S10 -> 0
B11: hend Eissa | G11: =E11-F11 -> 0 | J11: done | R11: 0 | T11: =R11-S11 -> 0
G12: =E12-F12 -> 0 | R12: 0 | T12: =R12-S12 -> 0
G13: =E13-F13 -> 0 | R13: 0 | T13: =R13-S13 -> 0
G14: =E14-F14 -> 0 | R14: 0 | T14: =R14-S14 -> 0
G15: =E15-F15 -> 0 | R15: 0 | T15: =R15-S15 -> 0
G16: =E16-F16 -> 0 | R16: 0 | T16: =R16-S16 -> 0
G17: =E17-F17 -> 0 | R17: 0 | T17: =R17-S17 -> 0
G18: =E18-F18 -> 0 | R18: 0 | T18: =R18-S18 -> 0
G19: =E19-F19 -> 0 | R19: 0 | T19: =R19-S19 -> 0
G20: =E20-F20 -> 0 | R20: 0 | T20: =R20-S20 -> 0
G21: =E21-F21 -> 0 | R21: 0 | T21: =R21-S21 -> 0
G22: =E22-F22 -> 0 | R22: 0 | T22: =R22-S22 -> 0
G23: =E23-F23 -> 0 | R23: 0 | T23: =R23-S23 -> 0
A24: 21 | G24: =E24-F24 -> 0 | R24: 0 | T24: =R24-S24 -> 0
A25: 22 | G25: =E25-F25 -> 0 | R25: 0 | T25: =R25-S25 -> 0
A26: 23 | G26: =E26-F26 -> 0 | R26: 0 | T26: =R26-S26 -> 0
A27: 24 | G27: =E27-F27 -> 0 | R27: 0 | T27: =R27-S27 -> 0
A28: 25 | G28: =E28-F28 -> 0 | R28: 0 | T28: =R28-S28 -> 0
A29: 26 | G29: =E29-F29 -> 0 | R29: 0 | T29: =R29-S29 -> 0
A30: 27 | G30: =E30-F30 -> 0 | R30: 0 | T30: =R30-S30 -> 0
A31: 28 | G31: =E31-F31 -> 0 | R31: 0 | T31: =R31-S31 -> 0
A32: 29 | G32: =E32-F32 -> 0 | R32: 0 | T32: =R32-S32 -> 0
A33: 30 | G33: =E33-F33 -> 0 | R33: 0 | T33: =R33-S33 -> 0
A34: 31 | G34: =E34-F34 -> 0 | R34: 0 | T34: =R34-S34 -> 0
A35: 32 | G35: =E35-F35 -> 0 | R35: 0 | T35: =R35-S35 -> 0
... A40: 37 | G40: =E40-F40 -> 0 | R40: 0 | T40: =R40-S40 -> 0
A41: Total | B41: =countif(B4:B40,"*") -> 8 | N41: Total | O41: =countif(O4:O40,"*") -> 5

Sheet Enn 2
A1: Enneagram 2 (AZ) 22 to 25 June CANCELLED | I1: Confirmation | J1: Attendance
A2: S. | B2: Client Name | C2: Phone Number | D2: Seller Name | E2: Payment | J2: Day 1 | K2: Day 2 | L2: Day 3 | M2: Day 4
E3: Course Fees | F3: Paid Amount | G3: Remaining Amount | H3: Notes
A4: 1 | B4: omnia taha | E4: 5350 | G4: =E4-F4 -> 5350 | I4: confirmed
A5: 2 | B5: mai el gammal | E5: 5350 | F5: 5350 | G5: =E5-F5 -> 0 | I5: confirmed
A6: 3 | B6: Ahmed el sherif | E6: 5350 | G6: =E6-F6 -> 5350 | I6: confirmed
A7: 4 | B7: Hana Tarek | E7: 5350 | G7: =E7-F7 -> 5350 | H7: not ok night | I7: confirmed
A8: 5 | B8: Rania Aziz | E8: 5350 | G8: =E8-F8 -> 5350 | I8: confirmed / value
A9: 6 | B9: heba osman | E9: 5350 | G9: =E9-E9 -> 0 | H9: OK night | I9: confirmed/online
E10: 5350 | G10: =E10-F10 -> 5350
E11: 5350 | G11: =E11-F11 -> 5350
A12: 8 | E12: 5350 | G12: =E12-F12 -> 5350
A13: 9 | B13: dina gamgoum | E13: 5350 | G13: =E13-F13 -> 5350
B14: manal Youssef | G14: =E14-F14 -> 0
A15: 10 | B15: ahmed zoghby | G15: =E15-F15 -> 0 | H15: will confirm night
G16: =E16-F16 -> 0
G17: =E17-F17 -> 0
G18: =E18-F18 -> 0
G19: =E19-F19 -> 0
G20: =E20-F20 -> 0
G21: =E21-F21 -> 0
G22: =E22-F22 -> 0
G23: =E23-F23 -> 0
G24: =E24-F24 -> 0
G25: =E25-F25 -> 0
G26: =E26-F26 -> 0
G27: =E27-F27 -> 0
... G36: =E36-F36 -> 0
B37: =countif(B4:B36,"*") -> 9

Sheet Enn 5
A1: Enneagram 5 (NC) 1 to 4 June | I1: Confirmation | J1: Attendance
A2: S. | B2: Client Name | C2: Phone Number | D2: Seller Name | E2: Payment | J2: Day 1 | K2: Day 2 | L2: Day 3 | M2: Day 4
E3: Course Fees | F3: Paid Amount | G3: Remaining Amount | H3: Notes
A4: 1 | B4: Ahmed kelinty | E4: 5000 | F4: 5000 | G4: =E4-F4 -> 0 | J4: done | K4: done | L4: Online | M4: done
A5: 2 | B5: Aicha | E5: 5000 | F5: 5000 | G5: =E5-F5 -> 0 | J5: done | K5: done | L5: done | M5: done
A6: 3 | B6: Noha Sharkawy | E6: 5000 | F6: 5000 | G6: =E6-F6 -> 0 | J6: done | K6: done | L6: done | M6: done
A7: 4 | B7: Noha Roshdy | E7: 5000 | F7: 5000 | G7: =E7-F7 -> 0 | J7: done | K7: done | L7: don | M7: done
A8: 5 | B8: hala ibrahim | E8: 5000 | F8: 5000 | G8: =E8-F8 -> 0 | J8: done | K8: done | L8: done | M8: done
A9: 6 | B9: menna bahaa | E9: 5000 | F9: 5000 | G9: =E9-F9 -> 0 | J9: done | K9: done | L9: done | M9: done
A10: 7 | B10: Hoda Khaled | E10: 5000 | F10: 5000 | G10: =E10-F10 -> 0 | J10: done | K10: done | L10: done | M10: done
A11: 8 | B11: Maysoon | E11: 5000 | F11: 5000 | G11: =E11-F11 -> 0 | J11: done | K11: done | L11: done | M11: done
A12: 9 | B12: sherin yehia | E12: 5000 | F12: 5000 | G12: =E12-F12 -> 0 | J12: done | K12: done | L12: done | M12: done
A13: 10 | B13: ghada sabry | E13: 5000 | F13: 5000 | G13: =E13-F13 -> 0 | J13: done | K13: done | L13: done | M13: done
A14: 11 | B14: Manal Ismail | E14: 5000 | F14: 5000 | G14: =E14-F14 -> 0 | J14: done | K14: done | L14: done | M14: done
A15: 12 | B15: deemah | E15: 5000 | F15: 5000 | G15: =E15-F15 -> 0 | J15: online | K15: online | L15: online | M15: online
... A17: 14 | B17: Rehab shoman | E17: 5000 | F17: 2000 | G17: =E17-F17 -> 3000 | J17: done | K17: done | L17: done | M17: done
A18: 15 | G18: =E18-F18 -> 0
A19: 16 | G19: =E19-F19 -> 0
A20: 17 | G20: =E20-F20 -> 0
A21: 18 | G21: =E21-F21 -> 0
A22: 19 | G22: =E22-F22 -> 0
A23: 20 | E23: 0 | G23: =E23-F23 -> 0
A24: 21 | E24: 0 | G24: =E24-F24 -> 0
A25: 22 | E25: 0 | G25: =E25-F25 -> 0
A26: 23 | E26: 0 | G26: =E26-F26 -> 0
A27: 24 | E27: 0 | G27: =E27-F27 -> 0
A28: 25 | E28: 0 | G28: =E28-F28 -> 0
A29: 26 | E29: 0 | G29: =E29-F29 -> 0
A30: 27 | E30: 0 | G30: =E30-F30 -> 0
A31: 28 | E31: 0 | G31: =E31-F31 -> 0
A32: 29 | E32: 0 | G32: =E32-F32 -> 0
A33: 30 | E33: 0 | G33: =E33-F33 -> 0
A34: 31 | E34: 0 | G34: =E34-F34 -> 0
... A40: 37 | E40: 0 | G40: =E40-F40 -> 0
A41: Total | B41: =countif(B4:B40,"*") -> 14 | E41: 0

Sheet Enn 6
A1: Enn 6 / 29 June - 2 July | I1: Confirmation | J1: Attendance
A2: S. | B2: Client Name | C2: Phone Number | D2: Seller Name | E2: Payment | J2: Day 1 | K2: Day 2 | L2: Day 3 | M2: Day 4
E3: Course Fees | F3: Paid Amount | G3: Remaining Amount | H3: Notes
A4: 1 | B4: Deemah | E4: 5650 | F4: 5650 | G4: =E4-F4 -> 0 | I4: confirmed/physical | J4: done | K4: done | L4: done
A5: 2 | B5: Rana Hussien | E5: 5650 | F5: 5650 | G5: =E5-F5 -> 0 | I5: confirmed | J5: online | K5: done | L5: done
A6: 3 | B6: Ahmed kelinty | E6: 5650 | G6: =E6-F6 -> 5650 | J6: done | K6: done | L6: done
A7: 4 | B7: Aicha | E7: 5650 | G7: =E7-F7 -> 5650 | J7: done | K7: done | L7: OUT
A8: 5 | B8: Noha Sharkawy | E8: 5650 | F8: 5600 | G8: =E8-F8 -> 50 | I8: confirmed | J8: done | K8: done | L8: done
A9: 6 | B9: Noha Roshdy | E9: 5650 | F9: 5600 | G9: =E9-F9 -> 50 | I9: confirmed | J9: dobe | K9: done | L9: done
A10: 7 | B10: menna bahaa | E10: 5650 | F10: 5600 | G10: =E10-F10 -> 50 | I10: confirmed | J10: done | K10: done | L10: done
A11: 8 | B11: Hoda Khaled | E11: 5650 | F11: 5650 | G11: =E11-F11 -> 0 | I11: confirmed | J11: done | K11: done | L11: done
A12: 9 | B12: Maysoon | E12: 5650 | F12: 4700 | G12: =E12-F12 -> 950 | I12: confirmed | J12: OUT | K12: done | L12: done
A13: 10 | B13: sherin yehia | E13: 5650 | F13: 5650 | G13: =E13-F13 -> 0 | I13: confirmed | J13: done | K13: done | L13: done
A14: 11 | B14: ghada sabry | E14: 5650 | F14: 5650 | G14: =E14-F14 -> 0 | I14: confirmed | J14: done | K14: done | L14: done
A15: 12 | B15: Manal Ismail | E15: 5650 | F15: 5650 | G15: =E15-F15 -> 0 | I15: confirmed | J15: done | K15: done | L15: done
A16: 13 | B16: sara darwish | E16: 5650 | F16: 5650 | G16: =E16-F16 -> 0 | I16: confirmed | J16: done | K16: done | L16: done
A17: 14 | B17: Ola | E17: 5650 | F17: 5650 | G17: =E17-F17 -> 0 | I17: confirmed | J17: done | K17: done | L17: done
A18: 15 | B18: Sara Essam | E18: 5650 | F18: 3250 | G18: =E18-F18 -> 2400 | H18: old credit 2400 | I18: confirmed | J18: done | K18: done | L18: done
A19: 16 | B19: Yasser | E19: 5650 | G19: =E19-F19 -> 5650 | I19: confirmed | J19: done | K19: done | L19: done
A20: 17 | B20: Ali Shaltout | E20: 5650 | F20: 5650 | G20: =E20-F20 -> 0 | J20: done | K20: done | L20: done
A21: 18 | B21: Fatma Wael | E21: 5650 | F21: 5650 | G21: =E21-F21 -> 0 | I21: confirmed | J21: done | K21: done | L21: done
A22: 19 | B22: Rasha S.Metwally | E22: 3955 | F22: 3955 | G22: =E22-F22 -> 0 | H22: 30% off / staff | I22: confirmed | J22: done | K22: done | L22: done
A23: 20 | B23: Karen | E23: 5650 | F23: 5650 | G23: =E23-F23 -> 0 | I23: confirmed | J23: done | K23: done | L23: done
E24: 0 | G24: =E24-F24 -> 0
A25: 21 | B25: Lama Elkordy | E25: 5650 | F25: 5650 | G25: =E25-F25 -> 0 | I25: online | L25: online
A26: 22 | B26: Doaa Kamel | E26: 5650 | F26: 2350 | G26: =E26-F26 -> 3300 | L26: done
E27: 0 | G27: =E27-F27 -> 0
E28: 0 | G28: =E28-F28 -> 0
E29: 0 | G29: =E29-F29 -> 0
E30: 0 | G30: =E30-F30 -> 0
E31: 0 | G31: =E31-F31 -> 0
E32: 0 | G32: =E32-F32 -> 0
E33: 0 | G33: =E33-F33 -> 0
A34: Total | B34: =countif(B6:B33,"*") -> 20

Sheet NLP 1
A1: NLP 1 (AZ) 15-16-17-18 June / Hend Eissa | I1: Confirmation | J1: Attendance
A2: S. | B2: Client Name | C2: Phone Number | D2: Seller Name | E2: Payment | J2: Day 1 | K2: Day 2 | L2: Day 3 | M2: Day 4
E3: Course Fees | F3: Paid Amount | G3: Remaining Amount | H3: Notes
A4: 1 | B4: Mayada Mounir | C4: 1005880522 | D4: Menna | E4: 3600 | F4: 3600 | G4: =E4-F4 -> 0 | J4: Done | K4: Done | L4: Done | M4: Done
A5: 2 | B5: Rania Medht | C5: 1033383373 | D5: Menna | E5: 3600 | F5: 3600 | G5: =E5-F5 -> 0 | J5: Done | K5: Done | L5: Done | M5: Done
A6: 3 | B6: Enas Khaliel | C6: 1005162673 | D6: Menna | E6: 3600 | F6: 3600 | G6: =E6-F6 -> 0 | J6: Done | K6: Done | L6: Done | M6: Done
A7: 4 | B7: Abir Ebrhaiem | C7: 1225662058 | D7: Menna | E7: 3600 | F7: 3600 | G7: =E7-F7 -> 0 | J7: Done | K7: Done | L7: Done | M7: Done
A8: 5 | B8: Maya El Aarabi | C8: 1221178895 | D8: Menna | E8: 3600 | F8: 3600 | G8: =E8-F8 -> 0 | J8: Done | K8: Done | L8: Done | M8: Done
A9: 6 | B9: Dalia khalil | C9: 1222110141 | D9: Nourhan | E9: 3600 | F9: 3600 | G9: =E9-F9 -> 0 | J9: Done | K9: Done | L9: Done | M9: Done
A10: 7 | B10: nouran l gzar | C10: 1063552208 | D10: Nourhan | E10: 3600 | F10: 3600 | G10: =E10-F10 -> 0 | J10: Done | K10: Done | L10: Done | M10: Done
A11: 8 | B11: Safy Moussa | C11: 971505511829 | D11: Menna | E11: 3600 | F11: 3600 | G11: =E11-F11 -> 0 | H11: live streaming/out of Egypt | J11: Online | K11: Online | L11: Absent | M11: Absent
A12: 9 | B12: Marwa shokr | C12: 1000057138 | D12: Menna | E12: 3600 | F12: 3600 | G12: =E12-F12 -> 0 | J12: Done | K12: Done | L12: Done | M12: Done
A13: 10 | B13: Omar Mohamed | C13: 102781000 | D13: Menna | E13: 3600 | F13: 3600 | G13: =E13-F13 -> 0 | J13: Done | K13: Done | L13: Done | M13: Done
A14: 11 | B14: Menna Helmy | E14: 3600 | G14: =E14-F14 -> 3600 | H14: Staff | J14: Done | K14: Done | L14: Done | M14: Done
A15: 12 | B15: Abir Ebrahem | C15: 0 122 566 2058 | D15: Adham | E15: 3600 | F15: 3759.5 | G15: =E15-F15 -> -159.5 | H15: online payment
A16: 13 | B16: amira Samier | D16: Menna | E16: 3600 | F16: 3600 | G16: =E16-F16 -> 0 | J16: Done | K16: Done | L16: Done | M16: Done
B19: Sum | E19: =SUM(E4:E18) -> 46800

Sheet NLP 3
A1: NLP 3 (AZ) 29-30 June & 1-2 July | H1: Confirmation | I1: Attendance
A2: S. | B2: Client Name | C2: Phone Number | D2: Payment | I2: Day 1 | J2: Day 2 | K2: Day 3 | L2: Day 4
D3: Course Fees | E3: Paid Amount | F3: Remaining Amount | G3: Notes
A4: 1 | B4: Adham | D4: 3465 | F4: =D4-E4 -> 3465 | G4: 30%disc | H4: Confirmed | I4: Yes | J4: Yes | K4: Yes | L4: Yes
A5: 2 | B5: Ahmed Atef | D5: 4250 | E5: 1000 | F5: =D5-E5 -> 3250 | H5: Confirmed | I5: Yes | J5: Yes | K5: Yes | L5: Yes
A6: 3 | B6: Rehab | D6: 4950 | E6: 4950 | F6: =D6-E6 -> 0 | H6: Confirmed | I6: Yes | J6: Yes | K6: Yes | L6: Yes
A7: 4 | B7: Khalid | D7: 4950 | E7: 4500 | F7: =D7-E7 -> 450 | H7: Confirmed | I7: Yes | J7: Yes | K7: Yes | L7: Yes
A8: 5 | B8: Nancy Naguib | D8: 4950 | E8: 4950 | F8: =D8-E8 -> 0 | H8: Confirmed | I8: Yes | J8: Yes | K8: Yes | L8: Yes
A9: 6 | B9: Nouran Gazzar | D9: 4950 | E9: 4950 | F9: =D9-E9 -> 0 | H9: Confirmed | I9: Yes | J9: Yes | K9: Yes | L9: Yes
A10: 7 | B10: Mayada | D10: 4500 | E10: 4500 | F10: =D10-E10 -> 0 | G10: Online | H10: Confirmed | I10: Yes | J10: Yes | K10: Yes | L10: Yes
A11: 8 | B11: Sara | D11: 4500 | E11: 4500 | F11: =D11-E11 -> 0 | G11: Online | H11: Confirmed | I11: Yes | J11: Yes | K11: Yes | L11: Yes
B13: Sum | D13: =SUM(D4:D12) -> 36515

Sheet NLP 2 
A1: NLP 2 (AZ)5 - 6 - 12 - 13 June | I1: Confirmation | J1: Attendance | W1: Confirmation
A2: S. | B2: Client Name | C2: Phone Number | D2: Seller Name | E2: Payment | J2: Day 1 | K2: Day 2 | L2: Day 3 | M2: Day 4
E3: Course Fees | F3: Paid Amount | G3: Remaining Amount | H3: Notes
A4: 1 | B4: iman elshekh | C4: 1223159241 | E4: 4950 | F4: 4950 | G4: =E4-F4 -> 0 | H4: 2000 gift coupon | I4: confirmed | J4: done | K4: done | L4: done | M4: done
A5: 2 | B5: Gawda mametvsara | C5: 1223162933 | E5: 4950 | F5: 2500 | G5: =E5-F5 -> 2450 | H5: will pay 5 July ISA | I5: confirmed | J5: done | K5: done | L5: done | M5: done
A6: 3 | B6: Adham Mohamed | E6: 3710 | F6: 3710 | G6: =E6-F6 -> 0 | H6: 30% staff disc | I6: confirmed | J6: done | K6: done | L6: done | M6: done
A7: 4 | B7: Rasha Metwally | E7: 3710 | G7: =E7-F7 -> 3710 | H7: 30% staff disc | J7: done | K7: done | L7: done | M7: done
A8: 5 | B8: Dalia essam | C8: 1222123322 | E8: 4950 | F8: 3900 | G8: =E8-F8 -> 1050 | H8: ليها 1050 كريدت،وهتكمل باقي الكورس اول يوم الصبح | I8: confirmed | J8: done | K8: done | L8: done | M8: done
A9: 6 | B9: Reham Zaher | E9: 4950 | F9: 2500 | G9: =E9-F9 -> 2450 | H9: value | I9: confirmed | J9: done | K9: done | L9: done | M9: done
G10: =E10-F10 -> 0
G11: =E11-F11 -> 0
G12: =E12-F12 -> 0
G13: =E13-F13 -> 0
G14: =E14-F14 -> 0
G15: =E15-F15 -> 0
G16: =E16-F16 -> 0
G17: =E17-F17 -> 0
G18: =E18-F18 -> 0
G19: =E19-F19 -> 0
G20: =E20-F20 -> 0
G21: =E21-F21 -> 0
... G25: =E25-F25 -> 0
A26: 25 | G26: =E26-F26 -> 0
A27: 26 | G27: =E27-F27 -> 0
A28: 27 | G28: =E28-F28 -> 0
A29: 28 | G29: =E29-F29 -> 0
A30: 29 | G30: =E30-F30 -> 0
A31: 30 | G31: =E31-F31 -> 0
A32: 31 | G32: =E32-F32 -> 0
A33: 32 | G33: =E33-F33 -> 0
A34: 33 | G34: =E34-F34 -> 0
A35: 34 | G35: =E35-F35 -> 0
A36: 35 | G36: =E36-F36 -> 0
A37: 36 | G37: =E37-F37 -> 0
A38: 37 | G38: =E38-F38 -> 0
A39: Total | B39: =countif(B4:B38,"*") -> 6

Sheet Mini CAW
A1: Mini CAW / 1 June / AZ / 10 - 3 P.M | I1: Confirmation | K1: CANCELLED mini caw 4 June NC | T1: Confirmation
A2: S. | B2: Client Name | C2: Seller Name | D2: Payment | K2: S. | L2: Client Name | M2: Phone Number | N2: Seller Name | O2: Payment
D4: Type | E4: Price | F4: Paid Amount | G4: Remaining Amount | H4: Notes | O4: Type | P4: Price | Q4: Paid Amount | R4: Remaining Amount | S4: Notes
A5: 1 | B5: Rehab Taha | C5: Menna | D5: Issue Holder | E5: 900 | F5: 900 | G5: =E5-F5 -> 0 | K5: 1 | R5: =P5-Q5 -> 0
A6: 2 | B6: Maha Sidky | C6: Menna | D6: Issue Holder | E6: 900 | F6: 900 | G6: =E6-F6 -> 0 | K6: 2 | R6: =P6-Q6 -> 0
A7: 3 | B7: Menna Helmy | D7: Participant | G7: =E7-F7 -> 0 | H7: for free | K7: 3 | R7: =P7-Q7 -> 0
A8: 4 | B8: Noha Abd El Wahab | C8: Menna | D8: Participant | G8: =E8-F8 -> 0 | H8: for free | K8: 4 | R8: =P8-Q8 -> 0
A9: 5 | B9: Heba Kamal | C9: Menna | D9: Participant | G9: =E9-F9 -> 0 | H9: for free | K9: 5 | R9: =P9-Q9 -> 0
A10: 6 | B10: Yara El Ghafaary | C10: Menna | D10: Participant | G10: =E10-F10 -> 0 | H10: for free | K10: 6 | R10: =P10-Q10 -> 0
A11: 7 | B11: Walaa Essam | C11: Menna | D11: Participant | G11: =E11-F11 -> 0 | H11: for free | K11: 7 | R11: =P11-Q11 -> 0
A12: 8 | B12: Nahla Allam | C12: Menna | D12: Participant | G12: =E12-F12 -> 0 | H12: for free | K12: 8 | R12: =P12-Q12 -> 0
A13: 9 | B13: Mai Abd El Bar | C13: Menna | D13: Participant | G13: =E13-F13 -> 0 | H13: for free | K13: 9 | R13: =P13-Q13 -> 0
A14: 10 | B14: Heba Mohasseb | C14: Menna | D14: Issue Holder | E14: 900 | F14: 900 | G14: =E14-F14 -> 0 | K14: 10 | R14: =P14-Q14 -> 0
A15: 11 | G15: =E15-F15 -> 0 | K15: 11 | R15: =P15-Q15 -> 0
A16: 12 | G16: =E16-F16 -> 0 | K16: 12 | R16: =P16-Q16 -> 0
A17: 13 | G17: =E17-F17 -> 0 | K17: 13 | R17: =P17-Q17 -> 0
A18: 14 | G18: =E18-F18 -> 0 | K18: 14 | R18: =P18-Q18 -> 0
A19: 15 | B19: =COUNTIFS(B5:B14,"*") -> 10 | G19: =E19-F19 -> 0 | K19: 15 | R19: =P19-Q19 -> 0
A20: Mini CAW / 23 June / AZ / 5 - 10 P.M | I20: Confirmation | K20: Mini CAW / 21 June / NC / 5 - 10 P.M | T20: Confirmation
A21: 1 | G21: =E21-F21 -> 0 | K21: 17 | R21: =P21-Q21 -> 0
A22: 2 | G22: =E22-F22 -> 0 | K22: 18 | R22: =P22-Q22 -> 0
A23: 3 | G23: =E23-F23 -> 0 | K23: 19 | R23: =P23-Q23 -> 0
A24: 4 | G24: =E24-F24 -> 0 | K24: 20 | R24: =P24-Q24 -> 0
A25: 5 | G25: =E25-F25 -> 0 | K25: 21 | R25: =P25-Q25 -> 0
A26: 6 | G26: =E26-F26 -> 0 | K26: 22 | R26: =P26-Q26 -> 0
A27: 7 | G27: =E27-F27 -> 0 | K27: 23 | R27: =P27-Q27 -> 0
A28: 8 | G28: =E28-F28 -> 0 | K28: 24 | R28: =P28-Q28 -> 0
A29: 9 | G29: =E29-F29 -> 0 | K29: 25 | R29: =P29-Q29 -> 0
A30: 10 | G30: =E30-F30 -> 0 | K30: 26 | R30: =P30-Q30 -> 0
A31: 11 | G31: =E31-F31 -> 0 | K31: 27 | R31: =P31-Q31 -> 0
A32: 12 | G32: =E32-F32 -> 0 | K32: 28 | R32: =P32-Q32 -> 0
... A35: 15 | G35: =E35-F35 -> 0 | K35: 31 | R35: =P35-Q35 -> 0
G36: =E36-F36 -> 0 | K36: 32 | R36: =P36-Q36 -> 0
G37: =E37-F37 -> 0 | K37: 33 | R37: =P37-Q37 -> 0
G38: =E38-F38 -> 0 | K38: 34 | R38: =P38-Q38 -> 0
G39: =E39-F39 -> 0 | K39: 35 | R39: =P39-Q39 -> 0
G40: =E40-F40 -> 0 | K40: 36 | R40: =P40-Q40 -> 0
G41: =E41-F41 -> 0 | K41: 37 | R41: =P41-Q41 -> 0
G42: =E42-F42 -> 0 | R42: =P42-Q42 -> 0
A43: Total | B43: =countif(B5:B42,"*") -> 10 | K43: Total | L43: =countif(L5:L42,"*") -> 0

Sheet NLP 4
A1: NLP 4 (NC) 20-21 & 27-28 July Sara Tarek | H1: Confirmation | I1: Attendance
A2: S. | B2: Client Name | C2: Phone Number | D2: Payment | I2: Day 1 | J2: Day 2 | K2: Day 3 | L2: Day 4
D3: Course Fees | E3: Paid Amount | F3: Remaining Amount | G3: Notes
A4: 1 | B4: Yomna | D4: 4250
A5: 2 | B5: Heba El Shayeb | D5: 4250
A6: 3 | B6: Gawdat | D6: 4250
A7: 4 | B7: Gasser | D7: 4950
A8: 5 | D8: 4950
A9: 6 | D9: 4950
A10: 7 | D10: 4950
A11: 8 | D11: 4950
A12: 9 | D12: 4950
A13: 10 | D13: 4950
A14: 11 | D14: 4950

Sheet NLP 5
A1: NLP 5 (NC) 22 Wed - 25 Sat June | H1: Confirmation | I1: Attendance
A2: S. | B2: Client Name | C2: Phone Number | D2: Payment | I2: Day 1 | J2: Day 2 | K2: Day 3 | L2: Day 4
D3: Course Fees | E3: Paid Amount | F3: Remaining Amount | G3: Notes
A4: 1 | B4: Nermine Salah | D4: 4250 | E4: 4250 | F4: =D4-E4 -> 0 | H4: confirmed | I4: Done | J4: Done | K4: Done | L4: Done
A5: 2 | B5: Radwa ahmed niazy | D5: 3910 | E5: 3910 | F5: =D5-E5 -> 0 | G5: 15 % disc / cooperative deal | H5: Confirmed | I5: Done | J5: Done | K5: Done | L5: Done
A6: 3 | B6: Heba el Shayeb | D6: 4250 | E6: 4250 | F6: =D6-E6 -> 0 | H6: Confirmed | I6: Done | J6: Done | K6: Done | L6: Done
A7: 4 | B7: Sherine Yehia | D7: 4250 | E7: 4250 | F7: =D7-E7 -> 0 | H7: confirmed | I7: Done | J7: Done | K7: Done | L7: Done
A8: 5 | B8: Ahmed Atef | D8: 4250 | E8: 4250 | F8: =D8-E8 -> 0 | H8: confirmed | I8: Done | J8: Done | K8: Done | L8: Done
A9: 6 | B9: Youmna Saber | D9: 4250 | E9: 4250 | F9: =D9-E9 -> 0 | G9: old credit | H9: confirmed | I9: Done | J9: Done | K9: Done | L9: Done
A10: 7 | B10: Ahmed Mamdouh | D10: 4250 | E10: 4250 | F10: =D10-E10 -> 0 | I10: Done | J10: Absent | K10: Absent | L10: Absent
B13: Sum | E13: =SUM(E4:E12) -> 29410

Sheet FC D1
A1: Diploma 1 (NC) 12 - 14 June | I1: Confirmation
A2: S. | B2: Client Name | C2: Phone Number | D2: Seller Name | E2: Payment
E3: Course Fees | F3: Paid Amount | G3: Remaining Amount | H3: Notes | J3: day1 | K3: day 2 | L3: day 3
A4: 1 | B4: Walaa Essam | D4: Menna | E4: 5700 | F4: 5300 | G4: =E4-F4 -> 400 | J4: done | K4: done
A5: 2 | B5: howida magdy | C5: 1222107931 | D5: Nourhan | E5: 5700 | F5: 5300 | G5: =E5-F5 -> 400 | H5: early bird | J5: done | K5: done
A6: 3 | B6: ahmed keshk | C6: 1227323363 | D6: Nourhan | E6: 5700 | F6: 5300 | G6: =E6-F6 -> 400 | H6: early bird | J6: done | K6: done
A7: 4 | B7: Adel Shalaby | D7: Menna | E7: 5700 | F7: 5300 | G7: =E7-F7 -> 400 | J7: done | K7: done
A8: 5 | B8: Gihan El Sharkawy | D8: Menna | E8: 5700 | F8: 5300 | G8: =E8-F8 -> 400 | J8: done | K8: done
A9: 6 | B9: Engy Mohy El Dien | D9: Menna | E9: 5700 | F9: 5300 | G9: =E9-F9 -> 400 | J9: Absent | K9: absent
A10: 7 | B10: Engy Khalied. | D10: Menna | E10: 5700 | F10: 5300 | G10: =E10-F10 -> 400 | J10: Absent | K10: absent
A11: 8 | B11: Aya Ehab | D11: Menna | E11: 5700 | F11: 5300 | J11: done | K11: done
A12: 9 | B12: Noha Nezzar | D12: Menna | E12: 5700 | F12: 1550 | G12: =E12-F12 -> 4150 | H12: as a resource will pay tomorrow
A13: 10 | E13: 5700 | G13: =E13-F13 -> 5700
A14: 11 | E14: 5700 | G14: =E14-F14 -> 5700
A15: 12 | E15: 5700 | G15: =E15-F15 -> 5700
A16: 13 | E16: 5700 | G16: =E16-F16 -> 5700
A17: 14 | E17: 5700 | G17: =E17-F17 -> 5700
A18: 15 | E18: 5700 | G18: =E18-F18 -> 5700
A19: 16 | E19: 5700 | G19: =E19-F19 -> 5700
A20: 17 | E20: 5700 | G20: =E20-F20 -> 5700
A21: 18 | E21: 5700 | G21: =E21-F21 -> 5700
A22: 19 | E22: 5700 | G22: =E22-F22 -> 5700
A23: 20 | E23: 5700 | G23: =E23-F23 -> 5700
A24: 21 | E24: 5700 | G24: =E24-F24 -> 5700
... A41: 38 | E41: 5700 | G41: =E41-F41 -> 5700
A42: Total | B42: =countif(B3:B41,"*") -> 9

Sheet FC P8
A1: Practitioner 8 (AZ) 8 - 11 June | I1: Confirmation
A2: S. | B2: Client Name | C2: Phone Number | D2: Seller Name | E2: Payment
E3: Course Fees | F3: Paid Amount | G3: Remaining Amount | H3: Notes
A4: 1 | B4: Sherin Rizk | D4: Menna | E4: 5700 | F4: 7600 | G4: =E4-F4 -> -1900
A5: 2 | B5: Rehab Shoman | D5: Menna | E5: 5700 | F5: 4000 | G5: =E5-F5 -> 1700
A6: 3 | B6: Rehab Taha | D6: Menna | E6: 5700 | F6: 3000 | G6: =E6-F6 -> 2700 | H6: by installment 3 months
A7: 4 | B7: Reham Ali | D7: Menna | E7: 5700 | F7: free | G7: =E7-F7 -> #VALUE!
A8: 5 | B8: Nashwa El Gharieb | D8: Menna | E8: 5700 | F8: free | G8: =E8-F8 -> #VALUE!
A9: 6 | B9: Emy Shaker | D9: Menna | E9: 5700 | F9: free | G9: =E9-F9 -> #VALUE!
A10: 7 | B10: Noha dadderr | D10: Menna | E10: 5700 | F10: free | G10: =E10-F10 -> #VALUE!
A11: 8 | B11: Engi Ali | D11: Menna | E11: 5700 | F11: 7000 | G11: =E11-F11 -> -1300
A12: 9 | B12: Sahar Mohamed | D12: Menna | E12: 5700 | F12: 7000 | G12: =E12-F12 -> -1300
A13: 10 | B13: Sarah Essam | D13: Menna | E13: 5700 | F13: 7000 | G13: =E13-F13 -> -1300
A14: 11 | B14: Heba Farid | D14: Menna | E14: 5700 | G14: =E14-F14 -> 5700
A15: 12 | B15: Reham Abd El Raziek | D15: Menna | E15: 5700 | F15: 500 | G15: =E15-F15 -> 5200
A16: 13 | B16: Hasna2 Yehia | D16: Menna | E16: 5700 | F16: 3000 | G16: =E16-F16 -> 2700
A17: 14 | B17: Amr El Kady | D17: Menna | E17: 5700 | F17: 7000 | G17: =E17-F17 -> -1300
A18: 15 | B18: Nesreen El Okda | D18: Menna | E18: 5700 | F18: 7000 | G18: =E18-F18 -> -1300
A19: 16 | B19: Doaa Kamal | D19: Menna | E19: 5700 | F19: 7000 | G19: =E19-F19 -> -1300
A20: 17 | B20: Pakinam El Samiry | D20: Menna | E20: 5700 | F20: 7000 | G20: =E20-F20 -> -1300
A21: 18 | B21: Seif Al Alfy | D21: Menna | E21: 5700 | F21: 7000 | G21: =E21-F21 -> -1300
A22: 19 | B22: Amira Zahran | D22: Menna | E22: 5700 | F22: free | G22: =E22-F22 -> #VALUE!
A23: 20 | B23: Gehan Azmy | D23: Menna | E23: 5700 | F23: 7000 | G23: =E23-F23 -> -1300
A24: 21 | B24: Mai Abd El Bar | D24: Menna | E24: 5700 | F24: resource | G24: =E24-F24 -> #VALUE!
A25: 22 | B25: Mai El Sholkamy | D25: Menna | E25: 5700 | F25: free | G25: =E25-F25 -> #VALUE!
A26: 23 | B26: Mona Ganoub | D26: Menna | E26: 5700 | F26: 2500 | G26: =E26-F26 -> 3200
A27: 24 | B27: Nabela Khalil | D27: Menna | E27: 5700 | F27: free | G27: =E27-F27 -> #VALUE!
A28: 25 | B28: Nagwan Samy | D28: Menna | E28: 5700 | F28: 7000 | G28: =E28-F28 -> -1300
A29: 26 | B29: Nancy Ashra | D29: Menna | E29: 5700 | F29: 7600 | G29: =E29-F29 -> -1900
A30: 27 | B30: Omnia Maher | D30: Menna | E30: 5700 | F30: 7000 | G30: =E30-F30 -> -1300
A31: 28 | B31: Sherin Omar | D31: Menna | E31: 5700 | G31: =E31-F31 -> 5700
A32: 29 | B32: Noha abd El wahab | D32: Menna | E32: 5700 | G32: =E32-F32 -> 5700
A33: 30 | B33: Samar Badr | D33: Menna | E33: 5700 | F33: 7000 | G33: =E33-F33 -> -1300
A34: 31 | B34: Samar Saied | D34: Menna | E34: 5700 | G34: =E34-F34 -> 5700
A35: 32 | B35: Samy Albalhan | D35: Menna | E35: 5700 | G35: =E35-F35 -> 5700
A36: 33 | B36: Shaima Abd El Aziem | D36: Menna | E36: 5700 | F36: 7000 | G36: =E36-F36 -> -1300
A37: 34 | B37: Sherine Saad | D37: Menna | E37: 5700 | F37: 7000 | G37: =E37-F37 -> -1300
A38: 35 | E38: 5700 | G38: =E38-F38 -> 5700
A39: 36 | E39: 5700 | G39: =E39-F39 -> 5700
A40: 37 | E40: 5700 | G40: =E40-F40 -> 5700
...

Sheet 9 Fears
A1: 9 fears ... one love (AZ) 28 June cancelled | I1: Confirmation
A2: S. | B2: Client Name | C2: Phone Number | D2: Seller Name | E2: Payment
E3: Course Fees | F3: Paid Amount | G3: Remaining Amount | H3: Notes
A4: 1 | B4: ola mohamed | D4: Rasha | E4: 850 | G4: =E4-F4 -> 850
A5: 2 | B5: Heba el shayeb | E5: 850 | F5: 850 | G5: =E5-F5 -> 0
A6: 3 | E6: 850 | G6: =E6-F6 -> 850
A7: 4 | E7: 850 | G7: =E7-F7 -> 850
A8: 5 | E8: 850 | G8: =E8-F8 -> 850
A9: 6 | E9: 850 | G9: =E9-F9 -> 850
A10: 7 | E10: 850 | G10: =E10-F10 -> 850
A11: 8 | E11: 850 | G11: =E11-F11 -> 850
A12: 9 | E12: 850 | G12: =E12-F12 -> 850
A13: 10 | E13: 850 | G13: =E13-F13 -> 850
A14: 11 | E14: 850 | G14: =E14-F14 -> 850
A15: 12 | E15: 850 | G15: =E15-F15 -> 850
A16: 13 | E16: 850 | G16: =E16-F16 -> 850
A17: 14 | E17: 850 | G17: =E17-F17 -> 850
... A27: 24 | E27: 850 | G27: =E27-F27 -> 850
A28: 25 | G28: =E28-F28 -> 0
A29: 26 | G29: =E29-F29 -> 0
A30: 27 | G30: =E30-F30 -> 0
A31: 28 | G31: =E31-F31 -> 0
A32: 29 | G32: =E32-F32 -> 0
A33: 30 | G33: =E33-F33 -> 0
A34: 31 | G34: =E34-F34 -> 0
A35: 32 | G35: =E35-F35 -> 0
A36: 33 | G36: =E36-F36 -> 0
A37: 34 | G37: =E37-F37 -> 0
A38: 35 | G38: =E38-F38 -> 0
A39: 36 | G39: =E39-F39 -> 0
... A41: 38 | G41: =E41-F41 -> 0
A42: Total | B42: =countif(B3:B41,"*") -> 2

Sheet EFT
A1: EFT 12 - 13 June | I1: Confirmation | K1: EFT 17 - 18 June | S1: Confirmation
A2: S. | B2: Client Name | C2: Phone Number | D2: Seller Name | E2: Payment | K2: S. | L2: Client Name | M2: Phone Number | N2: Seller Name | O2: Payment
E3: Course Fees | F3: Paid Amount | G3: Remaining Amount | H3: Notes | O3: Course Fees | P3: Paid Amount | Q3: Remaining Amount | R3: Notes
A4: 1 | B4: sara essam | D4: israa | E4: 2400 | F4: 2400 | G4: =E4-F4 -> 0 | K4: 1 | O4: 0 | Q4: =O4-P4 -> 0
A5: 2 | E5: 0 | G5: =E5-F5 -> 0 | K5: 2 | O5: 0 | Q5: =O5-P5 -> 0
A6: 3 | E6: 0 | G6: =E6-F6 -> 0 | K6: 3 | O6: 0 | Q6: =O6-P6 -> 0
A7: 4 | E7: 0 | G7: =E7-F7 -> 0 | K7: 4 | O7: 0 | Q7: =O7-P7 -> 0
A8: 5 | E8: 0 | G8: =E8-F8 -> 0 | K8: 5 | O8: 0 | Q8: =O8-P8 -> 0
A9: 6 | E9: 0 | G9: =E9-F9 -> 0 | K9: 6 | O9: 0 | Q9: =O9-P9 -> 0
A10: 7 | E10: 0 | K10: 7 | O10: 0 | Q10: =O10-P10 -> 0
A11: 8 | E11: 0 | G11: =E11-F11 -> 0 | K11: 8 | O11: 0 | Q11: =O11-P11 -> 0
A12: 9 | E12: 0 | G12: =E12-F12 -> 0 | K12: 9 | O12: 0 | Q12: =O12-P12 -> 0
A13: 10 | E13: 0 | G13: =E13-F13 -> 0 | K13: 10 | O13: 0 | Q13: =O13-P13 -> 0
A14: 11 | E14: 0 | G14: =E14-F14 -> 0 | K14: 11 | O14: 0 | Q14: =O14-P14 -> 0
A15: 12 | E15: 0 | G15: =E15-F15 -> 0 | K15: 12 | O15: 0 | Q15: =O15-P15 -> 0
A16: 13 | E16: 0 | G16: =E16-F16 -> 0 | K16: 13 | O16: 0 | Q16: =O16-P16 -> 0
A17: 14 | E17: 0 | G17: =E17-F17 -> 0 | K17: 14 | O17: 0 | Q17: =O17-P17 -> 0
A18: 15 | E18: 0 | G18: =E18-F18 -> 0 | K18: 15 | O18: 0 | Q18: =O18-P18 -> 0
A19: 16 | E19: 0 | G19: =E19-F19 -> 0 | K19: 16 | O19: 0 | Q19: =O19-P19 -> 0
A20: 17 | E20: 0 | G20: =E20-F20 -> 0 | K20: 17 | O20: 0 | Q20: =O20-P20 -> 0
A21: 18 | E21: 0 | G21: =E21-F21 -> 0 | K21: 18 | O21: 0 | Q21: =O21-P21 -> 0
A22: 19 | E22: 0 | G22: =E22-F22 -> 0 | K22: 19 | O22: 0 | Q22: =O22-P22 -> 0
... A41: 38 | E41: 0 | G41: =E41-F41 -> 0 | K41: 38 | O41: 0 | Q41: =O41-P41 -> 0
A42: Total | B42: =countif(B3:B41,"*") -> 1 | E42: 0 | K42: Total | L42: =countif(L3:L41,"*") -> 0 | O42: 0

Sheet Shadow in Relationship
A1: Shadows in Relationship (AZ) 2 - 4 June ( cancelled) | I1: Confirmation
B2: normal price: 1800 | D2: early bird:1200 | F2: couples:1800
A3: S. | B3: Client Name | C3: Phone Number | D3: Seller Name | E3: Payment
E4: Course Fees | F4: Paid Amount | G4: Remaining Amount | H4: Notes
A5: 1 | B5: Nadien Abou Bakr | C5: 0 122 218 0089 | D5: Rasha | E5: 1200 | F5: 1200 | G5: =E5-F5 -> 0
A6: 2 | G6: =E6-F6 -> 0
A7: 3 | G7: =E7-F7 -> 0
A8: 4 | G8: =E8-F8 -> 0
A9: 5 | G9: =E9-F9 -> 0
A10: 6 | G10: =E10-F10 -> 0
A11: 7 | G11: =E11-F11 -> 0
A12: 8 | G12: =E12-F12 -> 0
A13: 9 | G13: =E13-F13 -> 0
A14: 10 | G14: =E14-F14 -> 0
A15: 11 | G15: =E15-F15 -> 0
A16: 12 | G16: =E16-F16 -> 0
A17: 13 | G17: =E17-F17 -> 0
... A42: 38 | G42: =E42-F42 -> 0
A43: Total | B43: =countif(B4:B42,"*") -> 1

Sheet Love yr femininty
A1: Love yr femininty - Online / 25 June / 8 - 10 p.m | I1: Confirmation | K1: Love yr femininty - Online / 29 June / 8 - 10 p.m | S1: Confirmation
A3: S. | B3: Client Name | C3: Phone Number | D3: Seller Name | E3: Payment | K3: S. | L3: Client Name | M3: Phone Number | N3: Seller Name | O3: Payment
E4: Course Fees | F4: Paid Amount | G4: Remaining Amount | H4: Notes | O4: Course Fees | P4: Paid Amount | Q4: Remaining Amount | R4: Notes
A5: 1 | G5: =E5-F5 -> 0 | K5: 1 | Q5: =O5-P5 -> 0
A6: 2 | G6: =E6-F6 -> 0 | K6: 2 | Q6: =O6-P6 -> 0
A7: 3 | G7: =E7-F7 -> 0 | K7: 3 | Q7: =O7-P7 -> 0
A8: 4 | G8: =E8-F8 -> 0 | K8: 4 | Q8: =O8-P8 -> 0
A9: 5 | G9: =E9-F9 -> 0 | K9: 5 | Q9: =O9-P9 -> 0
A10: 6 | G10: =E10-F10 -> 0 | K10: 6 | Q10: =O10-P10 -> 0
A11: 7 | G11: =E11-F11 -> 0 | K11: 7 | Q11: =O11-P11 -> 0
A12: 8 | G12: =E12-F12 -> 0 | K12: 8 | Q12: =O12-P12 -> 0
A13: 9 | G13: =E13-F13 -> 0 | K13: 9 | Q13: =O13-P13 -> 0
A14: 10 | G14: =E14-F14 -> 0 | K14: 10 | Q14: =O14-P14 -> 0
A15: 11 | G15: =E15-F15 -> 0 | K15: 11 | Q15: =O15-P15 -> 0
A16: 12 | G16: =E16-F16 -> 0 | K16: 12 | Q16: =O16-P16 -> 0
... A42: 38 | G42: =E42-F42 -> 0 | K42: 38 | Q42: =O42-P42 -> 0
A43: Total | B43: =countif(B4:B42,"*") -> 0 | K43: Total | L43: =countif(L4:L42,"*") -> 0

Sheet Reiki Master
A1: Reiki Master (AZ) 16-18 June | I1: Confirmation
A2: S. | B2: Client Name | C2: Phone Number | D2: Seller Name | E2: Payment
E3: Course Fees | F3: Paid Amount | G3: Remaining Amount | H3: Notes | J3: Day 1 | K3: Day 2 | L3: Day 3
A4: 1 | B4: Mai Dahab | C4: 1002518386 | D4: Mariam | E4: 0 | G4: =E4-F4 -> 0 | H4: assistant | J4: TRUE | K4: TRUE | L4: TRUE
A5: 2 | B5: sarah Wahba | C5: 1062504778 | D5: Mariam | E5: 6000 | F5: 6000 | G5: =E5-F5 -> 0 | H5: done payment | J5: TRUE | K5: TRUE | L5: TRUE
A6: 3 | B6: Sarah Shaltout | C6: 1060707914 | D6: Mariam | E6: 6000 | F6: 6000 | G6: =E6-F6 -> 0 | H6: done payment | J6: TRUE | K6: TRUE | L6: TRUE
A7: 4 | B7: Reham Ali | C7: 1001409055 | D7: Mariam | E7: 6000 | F7: 6000 | G7: =E7-F7 -> 0 | H7: done payment | J7: TRUE | K7: TRUE | L7: TRUE
A8: 5 | B8: Abeer Abdelqader | C8: 1005699978 | D8: Mariam | E8: 6000 | F8: 6000 | G8: =E8-F8 -> 0 | H8: done payment | J8: TRUE | K8: TRUE | L8: TRUE
A9: 6 | B9: maye abdelbar | C9: 1002872618 | D9: Mariam | E9: 6000 | F9: 6000 | G9: =E9-F9 -> 0 | H9: done payment | J9: TRUE | K9: TRUE | L9: TRUE
A10: 7 | B10: omnia Maher | C10: 1270190006 | D10: Mariam | E10: 6000 | F10: 6000 | G10: =E10-F10 -> 0 | H10: done payment | J10: TRUE | K10: TRUE | L10: TRUE
A11: 8 | B11: Fatma Wael | C11: 1227447039 | D11: Mariam | E11: 6000 | F11: 3000 | G11: =E11-F11 -> 3000 | H11: will pay in july | J11: TRUE | K11: TRUE | L11: TRUE
A12: 9 | B12: Yara El ghaffary | C12: 1008794369 | D12: Mariam | E12: 6000 | F12: 6000 | G12: =E12-F12 -> 0 | H12: done payment | J12: TRUE | K12: TRUE | L12: TRUE
A13: 10 | B13: Marwa Gamal | C13: 1150056000 | D13: Mariam | E13: 6000 | F13: 6000 | G13: =E13-F13 -> 0 | H13: done payment | J13: TRUE | K13: TRUE | L13: TRUE
A14: 11 | B14: Amir Zarif | C14: 1001703976 | D14: Mariam | E14: 6000 | F14: 6000 | G14: =E14-F14 -> 0 | H14: done payment | J14: TRUE | K14: TRUE | L14: TRUE
A15: 12 | B15: sherine omar (paid) | C15: 1026205787 | D15: Mariam | E15: 6000 | F15: 6000 | G15: =E15-F15 -> 0 | H15: done payment | J15: TRUE | K15: TRUE | L15: TRUE
A16: 13 | B16: Ghada Taha | C16: 1001474499 | D16: Mariam | E16: 6000 | F16: 6000 | G16: =E16-F16 -> 0 | H16: done payment | J16: TRUE | K16: TRUE | L16: TRUE
... A19: 16 | B19: Sahar Mohamed | C19: 1001418428 | D19: Mariam | E19: 6000 | F19: 6000 | G19: =E19-F19 -> 0 | H19: done payment | J19: TRUE | K19: TRUE | L19: TRUE
A20: 17
A21: 18 | G21: =E21-F21 -> 0
A22: 19 | G22: =E22-F22 -> 0
A23: 20 | G23: =E23-F23 -> 0
A24: 21 | G24: =E24-F24 -> 0
A25: 22 | G25: =E25-F25 -> 0
A26: 23 | G26: =E26-F26 -> 0
A27: 24 | G27: =E27-F27 -> 0
A28: 25 | G28: =E28-F28 -> 0
A29: 26 | G29: =E29-F29 -> 0
A30: 27 | G30: =E30-F30 -> 0
A31: 28 | G31: =E31-F31 -> 0
A32: 29 | G32: =E32-F32 -> 0
... A38: 35 | G38: =E38-F38 -> 0
A39: Total | B39: =countif(B4:B38,"*") -> 17

Sheet Reiki D
A1: Reiki 1 (AZ) 30 June & 1-2 July | I1: Confirmation | R1: Reiki 1 (NC) 20-21-22 June | V1: Confirmation
A2: S. | B2: Client Name | C2: Phone Number | D2: Seller Name | E2: Payment | N2: S. | O2: Client Name | P2: Phone Number | Q2: Seller Name | R2: Payment
E3: Course Fees | F3: Paid Amount | G3: Remaining Amount | H3: Notes | J3: Day 1 | K3: Day 2 | L3: Day 3 | R3: Course Fees | S3: Paid Amount | T3: Remaining Amount | U3: Notes | W3: day 1 | X3: day2 | Y3: day3
A4: 1 | B4: Manar Mady | C4: 1116754449 | D4: Menna | E4: 3600 | F4: 3300 | G4: =E4-F4 -> 300 | J4: TRUE | K4: TRUE | L4: TRUE | N4: 1 | O4: Sama Hamada | Q4: Menna | R4: 3600 | S4: 3350 | T4: =R4-S4 -> 250 | W4: done | X4: done | Y4: done
A5: 2 | B5: shimaa ibrahim | C5: 01002071960 | D5: Nourhan | E5: 3600 | F5: 3350 | G5: =E5-F5 -> 250 | H5: early bird | J5: TRUE | K5: TRUE | L5: TRUE | N5: 2 | O5: Lamia Khalil | Q5: Menna | R5: 3600 | T5: =R5-S5 -> 3600 | W5: done | X5: done | Y5: done
A6: 3 | B6: Yassmine Mokhtar | C6: 10019111918 | D6: Menna | E6: 3600 | F6: 3350 | G6: =E6-F6 -> 250 | J6: TRUE | K6: TRUE | L6: TRUE | N6: 3 | O6: doha medhat | P6: 1020088272 | Q6: Nourhan | R6: 3600 | S6: 3600 | T6: =R6-S6 -> 0 | U6: 3 days are not enough/ great | W6: done | X6: done | Y6: done
A7: 4 | B7: maram ahmed | C7: 1065622777 | D7: Mariam | E7: 3600 | F7: 1800 | G7: =E7-F7 -> 1800 | H7: 50% repetition | J7: TRUE | K7: TRUE | L7: TRUE | N7: 4 | O7: Rasha Mohamed | Q7: Menna | R7: 3600 | S7: 3350 | T7: =R7-S7 -> 250 | W7: done | X7: done | Y7: done
A8: 5 | B8: dina nabhan | C8: 1023720002 | D8: Mariam | E8: 3600 | F8: 3350 | G8: =E8-F8 -> 250 | H8: early bird | J8: TRUE | K8: TRUE | L8: TRUE | N8: 5 | O8: Enas | Q8: Menna | R8: 3600 | S8: 3350 | T8: =R8-S8 -> 250 | U8: wants to be more than 3 days | W8: done | X8: done | Y8: done
A9: 6 | E9: 3600 | G9: =E9-F9 -> 3600 | N9: 6 | O9: heba l refaay | P9: 0 100 080 4134 | Q9: Nourhan | R9: 3600 | S9: 3600 | T9: =R9-S9 -> 0 | W9: done | X9: will attend next round | Y9: will attend next round
A10: 7 | E10: 3600 | G10: =E10-F10 -> 3600 | N10: 7 | O10: Reham Heikal | Q10: Menna | R10: 3600 | S10: 3350 | T10: =R10-S10 -> 250 | U10: all perfect | W10: done | X10: done | Y10: done
A11: 8 | E11: 3600 | G11: =E11-F11 -> 3600 | N11: 8 | R11: 3600 | T11: =R11-S11 -> 3600
A12: 9 | E12: 3600 | G12: =E12-F12 -> 3600 | N12: 9 | R12: 3600 | T12: =R12-S12 -> 3600
A13: 10 | E13: 3600 | G13: =E13-F13 -> 3600 | N13: 10 | R13: 3600 | T13: =R13-S13 -> 3600
A14: 11 | E14: 3600 | G14: =E14-F14 -> 3600 | N14: 11 | R14: 3600 | T14: =R14-S14 -> 3600
A15: 12 | E15: 3600 | G15: =E15-F15 -> 3600 | N15: 12 | R15: 3600 | T15: =R15-S15 -> 3600
A16: 13 | E16: 3600 | G16: =E16-F16 -> 3600 | N16: 13 | R16: 3600 | T16: =R16-S16 -> 3600
A17: 14 | E17: 3600 | G17: =E17-F17 -> 3600 | N17: 14 | R17: 3600 | T17: =R17-S17 -> 3600
A18: 15 | E18: 3600 | G18: =E18-F18 -> 3600 | N18: 15 | R18: 3600 | T18: =R18-S18 -> 3600
A19: 16 | E19: 3600 | G19: =E19-F19 -> 3600 | N19: 16 | R19: 3600 | T19: =R19-S19 -> 3600
A20: 17 | E20: 3600 | G20: =E20-F20 -> 3600 | N20: 17 | R20: 3600 | T20: =R20-S20 -> 3600
A21: 18 | E21: 3600 | G21: =E21-F21 -> 3600 | N21: total | O21: =countif(O4:O20,"*") -> 7
A22: 19 | E22: 3600 | G22: =E22-F22 -> 3600
A23: 20 | E23: 3600 | G23: =E23-F23 -> 3600
A24: 21 | E24: 3600 | G24: =E24-F24 -> 3600
A25: 22 | E25: 3600 | G25: =E25-F25 -> 3600
A26: 23 | E26: 3600 | G26: =E26-F26 -> 3600
A27: 24 | E27: 3600 | G27: =E27-F27 -> 3600
A28: 25 | E28: 3600 | G28: =E28-F28 -> 3600
A29: 26 | E29: 3600 | G29: =E29-F29 -> 3600
A30: 27 | E30: 3600 | G30: =E30-F30 -> 3600
A31: 28 | E31: 3600 | G31: =E31-F31 -> 3600
A32: 29 | E32: 3600 | G32: =E32-F32 -> 3600
A33: 30 | E33: 3600 | G33: =E33-F33 -> 3600
... A40: 37 | E40: 3600 | G40: =E40-F40 -> 3600
A41: Total | B41: =countif(B4:B40,"*") -> 5

Sheet RK Retreat
A1: Reiki Retreat 24 - 25 June | I1: Confirmation
A2: normal price:2650 | C2: early bird :2400 | E2: RK community normal price 2300 | G2: RK community early bird 2200
A3: S. | B3: Client Name | C3: Phone Number | D3: Seller Name | E3: Payment
E4: Course Fees | F4: Paid Amount | G4: Remaining Amount | H4: Notes
A5: 1 | B5: Reham Reda | C5: 1001998929 | D5: Mariam | E5: 2650 | F5: 2400 | G5: =E5-F5 -> 250 | H5: early bird // no ans
A6: 2 | B6: Sahar Elbakly | C6: 1001688863 | D6: Mariam | E6: 2650 | F6: 2200 | G6: =E6-F6 -> 450 | H6: not a community member// 200 left // transaction to enneagram module done
A7: 3 | B7: Amani Salah | C7: 1223259536 | D7: Mariam | E7: 2650 | F7: 2400 | G7: =E7-F7 -> 250 | H7: early bird // will transact it
A8: 4 | B8: mahmoud soliman | C8: 1123060586 | D8: Mariam | E8: 2650 | F8: 2300 | G8: =E8-F8 -> 350 | H8: refund done
A9: 5 | B9: Riham Sadek | D9: Menna | E9: 2650 | F9: 2400 | G9: =E9-F9 -> 250 | H9: (SINGLE ROOM+850) + (500 session with rania and osama) =3750
A10: 6 | B10: maram elzayat | C10: 1065622777 | D10: Nourhan | E10: 2650 | F10: 2650 | G10: =E10-F10 -> 0 | H10: paid will confirm tomorrow
A11: 7 | B11: hanan yousef | C11: 1143556545 | D11: Nourhan | E11: 2650 | F11: 2600 | G11: =E11-F11 -> 50 | H11: no ans
A12: 8 | B12: reem osman | C12: 1222339029 | D12: Nourhan | E12: 2650 | F12: 2300 | G12: =E12-F12 -> 350 | H12: community // will go by car // no ans
A13: 9 | B13: sherry elgalally | C13: 1000007225 | D13: Nourhan | E13: 2650 | F13: 2650 | G13: =E13-F13 -> 0 | H13: will go by car // refund
A14: 10 | E14: 2650 | G14: =E14-F14 -> 2650
A15: 11 | E15: 2650 | G15: =E15-F15 -> 2650
A16: 12 | E16: 2650 | G16: =E16-F16 -> 2650
A17: 13 | E17: 2650 | G17: =E17-F17 -> 2650
A18: 14 | E18: 2650 | G18: =E18-F18 -> 2650
A19: 15 | E19: 2650 | G19: =E19-F19 -> 2650
A20: 16 | E20: 2650 | G20: =E20-F20 -> 2650
A21: 17 | E21: 2650 | G21: =E21-F21 -> 2650
A22: 18 | E22: 2650 | G22: =E22-F22 -> 2650
A23: 19 | E23: 2650 | G23: =E23-F23 -> 2650
A24: 20 | E24: 2650 | G24: =E24-F24 -> 2650
A25: 21 | E25: 2650 | G25: =E25-F25 -> 2650
... A41: 37 | E41: 2650 | G41: =E41-F41 -> 2650
A42: 38 | B42: =countif(B4:B41,"*") -> 9
A43: 39
A44: 40
A45: 41
A46: 42
A47: 43
A48: 44
A49: 45

Sheet Healing the shadow
A1: Healing the shadow - RK workshop / 6 June / AZ 5:03 - 9 p.m | I1: Confirmation | K1: Healing the shadow - RK workshop / 10 June / NC 9 a.m - 12 p.m | S1: Confirmation
A3: S. | B3: Client Name | C3: Phone Number | D3: Seller Name | E3: Payment | K3: S. | L3: Client Name | M3: Phone Number | N3: Seller Name | O3: Payment
E4: Course Fees | F4: Paid Amount | G4: Remaining Amount | H4: Notes | O4: Course Fees | P4: Paid Amount | Q4: Remaining Amount | R4: Notes
A5: 1 | B5: sherine omar | C5: 1026205787 | D5: Mariam | E5: 650 | G5: =E5-F5 -> 650 | K5: 1 | L5: hoda sami | M5: 1005488680 | N5: Mariam | O5: 650 | P5: 575 | Q5: =O5-P5 -> 75 | R5: 2300 ( 4pck offer) Done
A6: 2 | B6: reem osman | C6: 1222339029 | D6: Mariam | E6: 650 | G6: =E6-F6 -> 650 | K6: 2 | L6: Mohamed Ali Khalaf | M6: 1271000560 | N6: Mariam | O6: 650 | P6: 650 | Q6: =O6-P6 -> 0 | R6: done
A7: 3 | B7: marwa ahmed mohamed | C7: 1554990370 | D7: Mariam | E7: 650 | G7: =E7-F7 -> 650 | K7: 3 | L7: marwa gamal | M7: 1150056000 | N7: Mariam | O7: 650 | P7: 575 | Q7: =O7-P7 -> 75 | R7: 2950 (4 pack +1 session 650)
A8: 4 | B8: omnia maher | C8: 1270190006 | D8: Mariam | E8: 550 | G8: =E8-F8 -> 550 | H8: community | K8: 4 | L8: fatma wael | M8: 1227447039 | N8: Mariam | O8: 550 | P8: 500 | Q8: =O8-P8 -> 50 | R8: reiki commuinty // paid 2000 community package
A9: 5 | B9: Dina Barakat | C9: 1000765611 | D9: Mariam | E9: 550 | G9: =E9-F9 -> 550 | H9: community | K9: 5 | L9: nitokriss | M9: 1227754672 | N9: Mariam | O9: 650 | P9: 650 | Q9: =O9-P9 -> 0 | R9: Done
A10: 6 | G10: =E10-H14 -> 0 | K10: 6 | L10: Ghada Taha | M10: 1001474499 | N10: Mariam | O10: 550 | P10: 550 | Q10: =O10-P10 -> 0 | R10: community
A11: 7 | G11: =E11-F11 -> 0 | K11: 7 | L11: gihan el sharkawy | M11: 1001600063 | N11: Mariam | O11: 750 | P11: 750 | Q11: =O11-P11 -> 0 | R11: other school payment
A12: 8 | G12: =E12-F12 -> 0 | K12: 8 | L12: yara el ghaffary | M12: 1008794369 | N12: Mariam | O12: 550 | P12: 550 | Q12: =O12-P12 -> 0 | R12: Done
A13: 9 | G13: =E13-F13 -> 0 | K13: 9 | L13: Amir Zarif | M13: 1001703976 | N13: Mariam | O13: 550 | P13: 550 | Q13: =O13-P13 -> 0 | R13: community
A14: 10 | G14: =E14-F14 -> 0 | K14: 10 | Q14: =O14-P14 -> 0
A15: 11 | G15: =E15-F15 -> 0 | K15: 11 | Q15: =O15-P15 -> 0
A16: 12 | G16: =E16-F16 -> 0 | K16: 12 | Q16: =O16-P16 -> 0
A17: 13 | G17: =E17-F17 -> 0 | K17: 13 | Q17: =O17-P17 -> 0
A18: 14 | G18: =E18-F18 -> 0 | K18: 14 | Q18: =O18-P18 -> 0
A19: 15 | G19: =E19-F19 -> 0 | K19: 15 | Q19: =O19-P19 -> 0
A20: 16 | G20: =E20-F20 -> 0 | K20: 16 | Q20: =O20-P20 -> 0
A21: 17 | G21: =E21-F21 -> 0 | K21: 17 | Q21: =O21-P21 -> 0
A22: 18 | G22: =E22-F22 -> 0 | K22: 18 | Q22: =O22-P22 -> 0
A23: 19 | G23: =E23-F23 -> 0 | K23: 19 | Q23: =O23-P23 -> 0
A24: 20 | G24: =E24-F24 -> 0 | K24: 20 | Q24: =O24-P24 -> 0
A25: 21 | G25: =E25-F25 -> 0 | K25: 21 | Q25: =O25-P25 -> 0
... A42: 38 | G42: =E42-F42 -> 0 | K42: 38 | Q42: =O42-P42 -> 0
A43: Total | B43: =countif(B4:B42,"*") -> 5 | K43: Total | L43: =countif(L4:L42,"*") -> 9

Sheet Healing the relationship
A1: Healing the relationship - RK workshop / 7 June / AZ 5:03 - 9 p.m | I1: Confirmation | K1: Healing the relationship - RK workshop / 10 June / NC 1 pm : 4 pm | S1: Confirmation
A3: S. | B3: Client Name | C3: Phone Number | D3: Seller Name | E3: Payment | K3: S. | L3: Client Name | M3: Phone Number | N3: Seller Name | O3: Payment
E4: Course Fees | F4: Paid Amount | G4: Remaining Amount | H4: Notes | O4: Course Fees | P4: Paid Amount | Q4: Remaining Amount | R4: Notes
A5: 1 | B5: sherine omar | C5: 1026205787 | D5: Mariam | E5: 650 | F5: 650 | G5: =E5-F5 -> 0 | K5: 1 | L5: hoda sami | M5: 1005488680 | N5: Mariam | O5: 650 | P5: 575 | Q5: =O5-P5 -> 75 | R5: ( 4 pack = 2300)
A6: 2 | B6: reem osman | C6: 1222339029 | D6: Mariam | E6: 650 | F6: 650 | G6: =E6-F6 -> 0 | K6: 2 | L6: Mohamed Ali Khalaf | M6: 1271000560 | N6: Mariam | O6: 650 | P6: 650 | Q6: =O6-P6 -> 0
A7: 3 | G7: =E7-F7 -> 0 | K7: 3 | L7: fatma wael | M7: 1227447039 | N7: Mariam | O7: 550 | P7: 500 | Q7: =O7-P7 -> 50 | R7: paid 2000 community package
A8: 4 | G8: =E8-F8 -> 0 | K8: 4 | L8: nitokriss | M8: 1227754672 | N8: Mariam | O8: 650 | P8: 650 | Q8: =O8-P8 -> 0
A9: 5 | G9: =E9-F9 -> 0 | K9: 5 | L9: Rania shafik | M9: 1207301111 | N9: Mariam | O9: 650 | P9: 650 | Q9: =O9-P9 -> 0
A10: 6 | G10: =E10-F10 -> 0 | K10: 6 | Q10: =O10-P10 -> 0
A11: 7 | G11: =E11-F11 -> 0 | K11: 7 | Q11: =O11-P11 -> 0
A12: 8 | G12: =E12-F12 -> 0 | K12: 8 | Q12: =O12-P12 -> 0
A13: 9 | G13: =E13-F13 -> 0 | K13: 9 | Q13: =O13-P13 -> 0
A14: 10 | G14: =E14-F14 -> 0 | K14: 10 | Q14: =O14-P14 -> 0
A15: 11 | G15: =E15-F15 -> 0 | K15: 11 | Q15: =O15-P15 -> 0
A16: 12 | G16: =E16-F16 -> 0 | K16: 12 | Q16: =O16-P16 -> 0
A17: 13 | G17: =E17-F17 -> 0 | K17: 13 | Q17: =O17-P17 -> 0
A18: 14 | G18: =E18-F18 -> 0 | K18: 14 | Q18: =O18-P18 -> 0
A19: 15 | G19: =E19-F19 -> 0 | K19: 15 | Q19: =O19-P19 -> 0
A20: 16 | G20: =E20-F20 -> 0 | K20: 16 | Q20: =O20-P20 -> 0
A21: 17 | G21: =E21-F21 -> 0 | K21: 17 | Q21: =O21-P21 -> 0
... A42: 38 | G42: =E42-F42 -> 0 | K42: 38 | Q42: =O42-P42 -> 0
A43: Total | B43: =countif(B4:B42,"*") -> 2 | K43: Total | L43: =countif(L4:L42,"*") -> 5

Sheet Love yr Body
A1: Love yr Body / 15 june / AZ / 7 - 10 p.m | I1: Confirmation | K1: Love yr Body ( TEENAGERS) / 18 june / AZ / 7:30- 9:30 p.m | S1: Confirmation
A3: S. | B3: Client Name | C3: Phone Number | D3: Seller Name | E3: Payment | K3: S. | L3: Client Name | M3: Phone Number | N3: Seller Name | O3: Payment
E4: Course Fees | F4: Paid Amount | G4: Remaining Amount | H4: Notes | O4: Course Fees | P4: Paid Amount | Q4: Remaining Amount | R4: Notes
A5: 1 | B5: Nermine Aly | D5: Menna | G5: =E5-F5 -> 0 | I5: confirm on the 15 | K5: 1 | Q5: =O5-P5 -> 0
A6: 2 | B6: Yara El Ghafarry | D6: Menna | G6: =E6-F6 -> 0 | I6: confirm on the 15 | K6: 2 | Q6: =O6-P6 -> 0
A7: 3 | B7: Marwa Mokhtar | D7: Menna | G7: =E7-F7 -> 0 | I7: cancel | K7: 3 | Q7: =O7-P7 -> 0
A8: 4 | B8: Randa Hussien | D8: Nourhan | G8: =E8-F8 -> 0 | K8: 4 | Q8: =O8-P8 -> 0
A9: 5 | B9: Dina Hussien | D9: Nourhan | G9: =E9-F9 -> 0 | K9: 5 | Q9: =O9-P9 -> 0
A10: 6 | B10: Abir Ibrahiem | D10: Menna | G10: =E10-F10 -> 0 | I10: confirm on the 15 | K10: 6 | Q10: =O10-P10 -> 0
A11: 7 | B11: Nabela Khalil | G11: =E11-F11 -> 0 | K11: 7 | Q11: =O11-P11 -> 0
A12: 8 | G12: =E12-F12 -> 0 | K12: 8 | Q12: =O12-P12 -> 0
A13: 9 | G13: =E13-F13 -> 0 | K13: 9 | Q13: =O13-P13 -> 0
A14: 10 | G14: =E14-F14 -> 0 | K14: 10 | Q14: =O14-P14 -> 0
A15: 11 | G15: =E15-F15 -> 0 | K15: 11 | Q15: =O15-P15 -> 0
A16: 12 | G16: =E16-F16 -> 0 | K16: 12 | Q16: =O16-P16 -> 0
A17: 13 | G17: =E17-F17 -> 0 | K17: 13 | Q17: =O17-P17 -> 0
A18: 14 | G18: =E18-F18 -> 0 | K18: 14 | Q18: =O18-P18 -> 0
A19: 15 | G19: =E19-F19 -> 0 | K19: 15 | Q19: =O19-P19 -> 0
A20: 16 | G20: =E20-F20 -> 0 | K20: 16 | Q20: =O20-P20 -> 0
A21: 17 | G21: =E21-F21 -> 0 | K21: 17 | Q21: =O21-P21 -> 0
A22: 18 | G22: =E22-F22 -> 0 | K22: 18 | Q22: =O22-P22 -> 0
A23: 19 | G23: =E23-F23 -> 0 | K23: 19 | Q23: =O23-P23 -> 0
... A42: 38 | G42: =E42-F42 -> 0 | K42: 38 | Q42: =O42-P42 -> 0
A43: Total | B43: =countif(B4:B42,"*") -> 7 | K43: Total | L43: =countif(L4:L42,"*") -> 0

Sheet Healing the inner child
A1: Healing the inner child - RK workshop / 8 June / AZ 5:30 - 9 p.m | I1: Confirmation | K1: Healing the inner child - RK workshop /11june / NC 9 a.m - 12 p.m | S1: Confirmation
A3: S. | B3: Client Name | C3: Phone Number | D3: Seller Name | E3: Payment | K3: S. | L3: Client Name | M3: Phone Number | N3: Seller Name | O3: Payment
E4: Course Fees | F4: Paid Amount | G4: Remaining Amount | H4: Notes | O4: Course Fees | P4: Paid Amount | Q4: Remaining Amount | R4: Notes
A5: 1 | B5: Omnia Maher | C5: 1270190006 | D5: Mariam | E5: 550 | G5: =E5-F5 -> 550 | H5: Community | K5: 1 | L5: Hoda Sami | M5: 1005488680 | N5: Mariam | O5: 650 | P5: 575 | Q5: =O5-P5 -> 75 | R5: 4 pck 2300
A6: 2 | B6: yara elghaffary | C6: 1008794369 | D6: Mariam | E6: 650 | G6: =E6-F6 -> 650 | K6: 2 | L6: Rania Shafiq | M6: 1207301111 | N6: Mariam | O6: 650 | P6: 650 | Q6: 0
A7: 3 | B7: Reem Osman | C7: 1222339029 | D7: Mariam | E7: 650 | G7: =E7-F7 -> 650 | K7: 3 | L7: Marwa Gamal (Paid) | M7: 1150056000 | N7: Mariam | O7: 650 | P7: 650 | Q7: =O7-P7 -> 0 | R7: 2950 (4 pck + 1 session)
A8: 4 | G8: =E8-F8 -> 0 | K8: 4 | L8: Fatma | M8: 1227447039 | N8: Mariam | O8: 550 | P8: 500 | Q8: =O8-P8 -> 50 | R8: paid 2000 community package
A9: 5 | G9: =E9-F9 -> 0 | K9: 5 | L9: Ghada Taha | M9: 1001474499 | N9: Mariam | O9: 550 | P9: 550 | Q9: =O9-P9 -> 0 | R9: community
A10: 6 | G10: =E10-F10 -> 0 | K10: 6 | L10: Amir Zarif | M10: 1001703976 | N10: Mariam | O10: 550 | P10: 550 | Q10: =O10-P10 -> 0 | R10: community
A11: 7 | G11: =E11-F11 -> 0 | K11: 7 | Q11: =O11-P6 -> -650
A12: 8 | G12: =E12-F12 -> 0 | K12: 8 | Q12: =O12-P12 -> 0
A13: 9 | G13: =E13-F13 -> 0 | K13: 9 | Q13: =O13-P13 -> 0
A14: 10 | G14: =E14-F14 -> 0 | K14: 10 | Q14: =O14-P14 -> 0
A15: 11 | G15: =E15-F15 -> 0 | K15: 11 | Q15: =O15-P15 -> 0
A16: 12 | G16: =E16-F16 -> 0 | K16: 12 | Q16: =O16-P16 -> 0
A17: 13 | G17: =E17-F17 -> 0 | K17: 13 | Q17: =O17-P17 -> 0
A18: 14 | G18: =E18-F18 -> 0 | K18: 14 | Q18: =O18-P18 -> 0
A19: 15 | G19: =E19-F19 -> 0 | K19: 15 | Q19: =O19-P19 -> 0
A20: 16 | G20: =E20-F20 -> 0 | K20: 16 | Q20: =O20-P20 -> 0
A21: 17 | G21: =E21-F21 -> 0 | K21: 17 | Q21: =O21-P21 -> 0
A22: 18 | G22: =E22-F22 -> 0 | K22: 18 | Q22: =O22-P22 -> 0
A23: 19 | G23: =E23-F23 -> 0 | K23: 19 | Q23: =O23-P23 -> 0
... A42: 38 | G42: =E42-F42 -> 0 | K42: 38 | Q42: =O42-P42 -> 0
A43: Total | B43: =countif(B4:B42,"*") -> 3 | K43: Total | L43: =countif(L4:L42,"*") -> 6

Sheet Trauma Healling
A1: Trauma Healling - RK workshop / 9 June / AZ 5:30 - 9 p.m | I1: Confirmation | K1: Trauma Healling - RK workshop / 11 June / NC/ 1 p.m - 4 p.m | S1: Confirmation
A3: S. | B3: Client Name | C3: Phone Number | D3: Seller Name | E3: Payment | K3: S. | L3: Client Name | M3: Phone Number | N3: Seller Name | O3: Payment
E4: Course Fees | F4: Paid Amount | G4: Remaining Amount | H4: Notes | O4: Course Fees | P4: Paid Amount | Q4: Remaining Amount | R4: Notes
A5: 1 | G5: =E5-F5 -> 0 | K5: 1 | L5: Hoda Sami | M5: 1005488680 | N5: Mariam | O5: 650 | P5: 575 | Q5: =O5-P5 -> 75 | R5: paid 2300 (4 pck)
A6: 2 | G6: =E6-F6 -> 0 | K6: 2 | L6: Marwa Gamal | N6: Mariam | O6: 650 | P6: 650 | Q6: =O6-P6 -> 0
A7: 3 | G7: =E7-F7 -> 0 | K7: 3 | L7: Fatma | M7: 1227447039 | N7: Mariam | O7: 550 | P7: 500 | Q7: =O7-P7 -> 50 | R7: paid 2000 community package
A8: 4 | G8: =E8-F8 -> 0 | K8: 4 | L8: Ghada Taha | N8: Mariam | O8: 550 | P8: 550 | Q8: =O8-P8 -> 0
A9: 5 | G9: =E9-F9 -> 0 | K9: 5 | L9: Rania shafiq | N9: Mariam | O9: 650 | P9: 650 | Q9: =O9-P9 -> 0
A10: 6 | G10: =E10-F10 -> 0 | K10: 6 | Q10: =O10-P10 -> 0
A11: 7 | G11: =E11-F11 -> 0 | K11: 7 | Q11: =O11-P11 -> 0
A12: 8 | G12: =E12-F12 -> 0 | K12: 8 | Q12: =O12-P12 -> 0
A13: 9 | G13: =E13-F13 -> 0 | K13: 9 | Q13: =O13-P13 -> 0
A14: 10 | G14: =E14-F14 -> 0 | K14: 10 | Q14: =O14-P14 -> 0
A15: 11 | G15: =E15-F15 -> 0 | K15: 11 | Q15: =O15-P15 -> 0
A16: 12 | G16: =E16-F16 -> 0 | K16: 12 | Q16: =O16-P16 -> 0
A17: 13 | G17: =E17-F17 -> 0 | K17: 13 | Q17: =O17-P17 -> 0
A18: 14 | G18: =E18-F18 -> 0 | K18: 14 | Q18: =O18-P18 -> 0
A19: 15 | G19: =E19-F19 -> 0 | K19: 15 | Q19: =O19-P19 -> 0
A20: 16 | G20: =E20-F20 -> 0 | K20: 16 | Q20: =O20-P20 -> 0
A21: 17 | G21: =E21-F21 -> 0 | K21: 17 | Q21: =O21-P21 -> 0
... A42: 38 | G42: =E42-F42 -> 0 | K42: 38 | Q42: =O42-P42 -> 0
A43: Total | B43: =countif(B4:B42,"*") -> 0 | K43: Total | L43: =countif(L4:L42,"*") -> 5

Sheet Reiki Open Healing Session
A1: Healing Circle AZ(27 June 6:00PM - 7:30PM) | K1: Free Reiki Master Class (Zoom) (23 June 7:00PM - 8:00PM)
A2: S. | B2: Client Name | C2: Phone Number | D2: Seller Name | E2: Price | I2: Confirmation | K2: S. | L2: Client Name | M2: Phone Number | N2: Seller Name | O2: Price | S2: Confirmation
E3: Event Fees | F3: Paid Amount | G3: Remaining Amount | H3: Notes | O3: Event Fees | P3: Paid Amount | Q3: Remaining Amount | R3: Notes
A4: 1 | E4: 250 | G4: =E4-F4 -> 250 | K4: 1 | O4: 0 | Q4: =O4-P4 -> 0
A5: 2 | E5: 250 | G5: =E5-F5 -> 250 | K5: 2 | O5: 0 | Q5: =O5-P5 -> 0
A6: 3 | E6: 250 | G6: =E6-F6 -> 250 | K6: 3 | O6: 0 | Q6: =O6-P6 -> 0
A7: 4 | E7: 250 | G7: =E6-F6 -> 250 | K7: 4 | O7: 0 | Q7: =O7-P7 -> 0
A8: 5 | E8: 250 | G8: =E8-F8 -> 250 | K8: 5 | O8: 0 | Q8: =O8-P8 -> 0
A9: 6 | E9: 250 | G9: =E9-F9 -> 250 | K9: 6 | O9: 0 | Q9: =O9-P9 -> 0
A10: 7 | E10: 250 | G10: =E10-F10 -> 250 | K10: 7 | O10: 0 | Q10: =O10-P10 -> 0
A11: 8 | E11: 250 | G11: =E11-F11 -> 250 | K11: 8 | O11: 0 | Q11: =O11-P11 -> 0
A12: 9 | E12: 250 | G12: =E12-F12 -> 250 | K12: 9 | O12: 0 | Q12: =O12-P12 -> 0
A13: 10 | E13: 250 | G13: =E13-F13 -> 250 | K13: 10 | O13: 0 | Q13: =O13-P13 -> 0
A14: 11 | E14: 250 | G14: =E14-F14 -> 250 | K14: 11 | O14: 0 | Q14: =O14-P14 -> 0
A15: 12 | E15: 250 | G15: =E15-F15 -> 250 | K15: 12 | O15: 0 | Q15: =O15-P15 -> 0
A16: 13 | E16: 250 | G16: =E16-F16 -> 250 | K16: 13 | O16: 0 | Q16: =O16-P16 -> 0
A17: 14 | E17: 250 | G17: =E17-F17 -> 250 | K17: 14 | O17: 0 | Q17: =O17-P17 -> 0
A18: 15 | E18: 250 | G18: =E18-F18 -> 250 | K18: 15 | O18: 0 | Q18: =O18-P18 -> 0
A19: 16 | E19: 250 | G19: =E19-F19 -> 250 | K19: 16 | O19: 0 | Q19: =O19-P19 -> 0
... A33: 30 | E33: 250 | G33: =E33-F33 -> 250 | K33: 30 | O33: 0 | Q33: =O33-P33 -> 0
